Workbook

Sheet STOCK
A1: Item | B1: Description | C1: Unit | D1: stock now | E1: Quantity
A3: 1 | B3: Suspension 2 way Hooks | C3: each | D3: 6600 | E3: =D3+'Materials in'!D3-'Materilas out'!D3 -> 7674
A4: 2 | B4: Suspension Triple Hooks | C4: each | D4: 2340 | E4: =D4+'Materials in'!D4-'Materilas out'!D4 -> 2190
A5: 3 | B5: Large X Bracket (Galvanized)600*600 | C5: each | D5: 75 | E5: =D5+'Materials in'!D5-'Materilas out'!D5 -> 468
A6: 4 | B6: Large X Bracket (Galvanized)400*400 | C6: each | D6: 230 | E6: =D6+'Materials in'!D6-'Materilas out'!D6 -> 318
A7: 5 | B7: Distribution slack bracket | C7: Each | D7: 0 | E7: =D7+'Materials in'!D7-'Materilas out'!D7 -> 0
A8: 6 | B8: STEEL Strapping 9.5mmx0.5mm (Labels- 1 Strap per Wooden Pole) (30m p. Box) | C8: Box | D8: 0 | E8: =D8+'Materials in'!D8-'Materilas out'!D8 -> 102
A9: 7 | B9: STEEL Buckles 9.5mm (Labels- 1 Buckle per Wooden Poles) (100 p. Box) | C9: Box | D9: 29 | E9: =D9+'Materials in'!D9-'Materilas out'!D9 -> 91
A10: 8 | B10: STEEL Strapping 19mmx0.5mm (Bosal- 4 Straps per Pole) (30m p. Box) | C10: Box | D10: 130 | E10: =D10+'Materials in'!D10-'Materilas out'!D10 -> 38
A11: 9 | B11: STEEL Buckles 19mm (Bosal- 4 Buckles per Pole) (100 p. Box) | C11: Box | D11: 183 | E11: =D11+'Materials in'!D11-'Materilas out'!D11 -> 82
A12: 10 | B12: D/END 4.8-6.2mm | C12: each | D12: 2520 | E12: =D12+'Materials in'!D12-'Materilas out'!D12 -> 3420
A13: 11 | B13: D/END 6-8mm | C13: each | D13: 7400 | E13: =D13+'Materials in'!D13-'Materilas out'!D13 -> 4200
A14: 12 | B14: D/END 9.2-9.5mm | C14: each | D14: 63 | E14: =D14+'Materials in'!D14-'Materilas out'!D14 -> 243
... A17: 15 | B17: 5+1 dome joint | C17: each | D17: 0 | E17: =D17+'Materials in'!D17-'Materilas out'!D17 -> -120
A18: 16 | B18: Drop Cable Closure Cs External Multi Drop Closure | 36 Fibre | 4 x Adaptor Holders MDC | C18: each | D18: 0 | E18: =D18+'Materials in'!D19-'Materilas out'!D18 -> 756
A19: 17 | B19: Feeder Enclosure Corning Enclosure BPEO -S1.5-FDP-DROP N501846A/CMJ | C19: each | D19: 159 | E19: =D19+'Materials in'!D20-'Materilas out'!D19 -> 109
A20: 18 | B20: LMJ | C20: each | D20: =11+9 -> 20 | E20: =D20+'Materials in'!D21-'Materilas out'!D20 -> 20
A21: 19 | B21: Duplex Mid Couplers LC-LC(UPC) | C21: each | D21: 2100 | E21: =D21+'Materials in'!D22-'Materilas out'!D21 -> 1300
A22: 20 | B22: Duplex Mid Couplers LC-LC(APC) | C22: each | D22: 2579 | E22: =D22+'Materials in'!D23-'Materilas out'!D22 -> 1579
A23: 21 | B23: Cartridge 19.1mm | C23: each | D23: 255 | E23: =D23+'Materials in'!D24-'Materilas out'!D23 -> 155
A24: 22 | B24: Cartriage 9.5mm | C24: each | D24: 216 | E24: =D24+'Materials in'!D25-'Materilas out'!D24 -> 81
A25: 23 | B25: Splice Protectors-FMSP | C25: each | D25: 7020 | E25: =D25+'Materials in'!D26-'Materilas out'!D25 -> 4220
A26: 24 | B26: SPLITTER BARE SM 1-2 (APC) | C26: each | D26: 6 | E26: =D26+'Materials in'!D27-'Materilas out'!D26 -> 6
A27: 25 | B27: SPLITTER BARE SM 1-8 (APC) | C27: each | D27: 111 | E27: =D27+'Materials in'!D28-'Materilas out'!D27 -> 112
A28: 26 | B28: SPLITTER BARE SM 1-16 (APC) | C28: each | D28: 0 | E28: =D28+'Materials in'!D29-'Materilas out'!D28 -> 0
A29: 27 | B29: SPLITTER BARE SM 1-32 (APC) | C29: each | D29: 13 | E29: =D29+'Materials in'!D30-'Materilas out'!D29 -> 13
A30: 28 | B30: SPLITTER PRECONNECTERISSED SM 1-8 (UPC) | C30: each | D30: 247 | E30: =D30+'Materials in'!D31-'Materilas out'!D30 -> 506
A31: 29 | B31: SPLITTER PRECONNECTERISSED SM 1-4 (APC) | C31: each | D31: 28 | E31: =D31+'Materials in'!D32-'Materilas out'!D31 -> 28
A32: 30 | B32: SPLITTER PRECONNECTERISSED SM 1-8 (APC) | C32: each | D32: 320 | E32: =D32+'Materials in'!D33-'Materilas out'!D32 -> 0
... A36: 34 | B36: 144F Mini Adss cable / Feeder 2KM&4KM / per roll | C36: m | D36: 0 | E36: =D36+'Materials in'!D37-'Materilas out'!D36 -> 0

Sheet Materials in
A1: Item | B1: Description | C1: Unit | D1: Quantity | E1: 45945 | F1: 45946 | G1: 45947 | H1: 45952 | I1: 45957 | J1: 45958 | K1: 45959 | L1: 45960 | M1: 45961 | N1: 45788 | O1: 45973 | P1: 45980 | Q1: 45980 | R1: date | S1: date | T1: date | U1: date | V1: date
A3: 1 | B3: Suspension 2 way Hooks | C3: each | D3: =SUM(E3:N3) -> 3724 | G3: 400 | H3: 700 | I3: 2000 | M3: 624
A4: 2 | B4: Suspension Triple Hooks | C4: each | D4: =SUM(E4:N4) -> 2600 | G4: =400+1100 -> 1500 | I4: 100 | M4: 1000
A5: 3 | B5: Large X Bracket (Galvanized)600*600 | C5: each | D5: =SUM(E5:N5) -> 530 | G5: 400 | M5: 130
A6: 4 | B6: Large X Bracket (Galvanized)400*400 | C6: each | D6: =SUM(E6:N6) -> 88 | M6: 88
A7: 5 | B7: Distribution slack bracket | C7: Each | D7: =SUM(E7:N7) -> 0
A8: 6 | B8: STEEL Strapping 9.5mmx0.5mm (Labels- 1 Strap per Wooden Pole) (30m p. Box) | C8: Box | D8: =SUM(E8:N8) -> 102 | K8: 102
A9: 7 | B9: STEEL Buckles 9.5mm (Labels- 1 Buckle per Wooden Poles) (100 p. Box) | C9: Box | D9: =SUM(E9:N9) -> 62 | K9: 62
A10: 8 | B10: STEEL Strapping 19mmx0.5mm (Bosal- 4 Straps per Pole) (30m p. Box) | C10: Box | D10: =SUM(E10:N10) -> 60 | H10: 60
A11: 9 | B11: STEEL Buckles 19mm (Bosal- 4 Buckles per Pole) (100 p. Box) | C11: Box | D11: =SUM(E11:N11) -> 36 | H11: 16 | M11: 20
A12: 10 | B12: D/END 4.8-6.2mm | C12: each | D12: =SUM(E12:N12) -> 4000 | I12: 2000 | L12: 2000
A13: 11 | B13: D/END 6-8mm | C13: each | D13: =SUM(E13:N13) -> 0
A14: 12 | B14: D/END 9.2-9.5mm | C14: each | D14: =SUM(E14:N14) -> 300 | F14: 300
A15: 13 | B15: D/END 9.5-10.5mm | C15: each | D15: =SUM(E15:N15) -> 0
A16: 14 | B16: D/END 15.6-17.3mm | C16: each | D16: =SUM(E16:N16) -> 0
A17: 15 | B17: 5+1 dome joint | C17: each | D17: =SUM(E17:N17) -> 0
A18: 16 | B18: 144F DOME JOINT CMJ | C18: each | J18: 23
A19: 17 | B19: Drop Cable Closure Cs External Multi Drop Closure | 36 Fibre | 4 x Adaptor Holders MDC | C19: each | D19: =SUM(E19:N19) -> 756 | G19: 756
A20: 18 | B20: Feeder Enclosure Corning Enclosure BPEO -S1.5-FDP-DROP N501846A/CMJ | C20: each | D20: =SUM(E20:N20) -> 0
A21: 19 | B21: LMJ | C21: each | D21: =SUM(E21:N21) -> 0
A22: 20 | B22: Duplex Mid Couplers LC-LC(UPC) | C22: each | D22: =SUM(E22:N22) -> 0
A23: 21 | B23: Duplex Mid Couplers LC-LC(APC) | C23: each | D23: =SUM(E23:N23) -> 0
A24: 22 | B24: Cartridge 19.1mm | C24: each | D24: =SUM(E24:N24) -> 0
A25: 23 | B25: Cartriage 9.5mm | C25: each | D25: =SUM(E25:N25) -> 0
A26: 24 | B26: Splice Protectors-FMSP | C26: each | D26: =SUM(E26:N26) -> 0
A27: 25 | B27: SPLITTER BARE SM 1-2 | C27: each | D27: =SUM(E27:N27) -> 0
A28: 26 | B28: SPLITTER BARE SM 1-8 | C28: each | D28: =SUM(E28:N28) -> 36 | H28: 36
A29: 27 | B29: SPLITTER BARE SM 1-16 | C29: each | D29: =SUM(E29:N29) -> 155 | E29: 155
A30: 28 | B30: SPLITTER BARE SM 1-32 | C30: each | D30: =SUM(E30:N30) -> 0
A31: 29 | B31: SPLITTER PRECONNECTERISSED SM 1-8 (UPC) | C31: each | D31: =SUM(E31:N31) -> 659 | E31: 659
A32: 30 | B32: SPLITTER PRECONNECTERISSED SM 1-4 (APC) | C32: each | D32: =SUM(E32:N32) -> 0
A33: 31 | B33: SPLITTER PRECONNECTERISSED SM 1-8 (APC) | C33: each | D33: =SUM(E33:N33) -> 1680 | E33: 1680
A34: 32 | B34: 12F Mini Adss cable / Distribution 2KM&4KM / per roll | C34: m | D34: =SUM(E34:N34) -> 0
A35: 33 | B35: 24F Mini Adss cable / Distribution 2KM&4KM / per roll | C35: m | D35: =SUM(E35:N35) -> 0
A36: 34 | B36: 72F Mini Adss cable / Feeder 2KM&4KM / per roll | C36: m | D36: =SUM(E36:N36) -> 0
A37: 35 | B37: 144F Mini Adss cable / Feeder 2KM&4KM / per roll | C37: m | D37: =SUM(E37:N37) -> 0
A38: 36 | B38: MDC plastic pole/wall mount bracket kiy | C38: m | D38: =SUM(E38:N38) -> 2150 | N38: 2150
A39: 37 | B39: strapping s/s 9,5mm x 0,5mm ( 30mt roll) | C39: each | D39: =SUM(E39:N39) -> 0
A40: 38 | B40: buckles s/s 9,5mm x 9,5mm x 0,5mm (100 per box) | C40: Box | D40: =SUM(E40:N40) -> 0
A41: 39 | B41: strapping s/s 19mm x 0,5mm (30mt roll) | C41: each | D41: =SUM(E41:N41) -> 0
...

Sheet Materilas out
A1: Item | B1: Description | C1: Unit | D1: Quantity | E1: 45946 | F1: 45951 | G1: 45952 | H1: 45958 | I1: 45959 | J1: 45968 | K1: date | L1: date | M1: date | N1: date | O1: date
A3: 1 | B3: Suspension 2 way Hooks | C3: each | D3: =SUM(E3:L3) -> 2650 | G3: 1400 | H3: 450 | I3: 800
A4: 2 | B4: Suspension Triple Hooks | C4: each | D4: =SUM(E4:L4) -> 2750 | G4: 200 | H4: 50 | I4: 2500
A5: 3 | B5: Large X Bracket (Galvanized)600*600 | C5: each | D5: =SUM(E5:L5) -> 137 | G5: 60 | H5: 32 | I5: 45
A6: 4 | B6: Large X Bracket (Galvanized)400*400 | C6: each | D6: =SUM(E6:L6) -> 0
A7: 5 | B7: Distribution slack bracket | C7: Each | D7: =SUM(E7:L7) -> 0
A8: 6 | B8: STEEL Strapping 9.5mmx0.5mm (Labels- 1 Strap per Wooden Pole) (30m p. Box) | C8: Box | D8: =SUM(E8:L8) -> 0
A9: 7 | B9: STEEL Buckles 9.5mm (Labels- 1 Buckle per Wooden Poles) (100 p. Box) | C9: Box | D9: =SUM(E9:L9) -> 0
A10: 8 | B10: STEEL Strapping 19mmx0.5mm (Bosal- 4 Straps per Pole) (30m p. Box) | C10: Box | D10: =SUM(E10:L10) -> 152 | G10: 50 | H10: 22 | I10: 80
A11: 9 | B11: STEEL Buckles 19mm (Bosal- 4 Buckles per Pole) (100 p. Box) | C11: Box | D11: =SUM(E11:L11) -> 137 | G11: 40 | H11: 14 | I11: 83
A12: 10 | B12: D/END 4.8-6.2mm | C12: each | D12: =SUM(E12:L12) -> 3100 | H12: 940 | I12: 2160
A13: 11 | B13: D/END 6-8mm | C13: each | D13: =SUM(E13:L13) -> 3200 | I13: 3200
A14: 12 | B14: D/END 9.2-9.5mm | C14: each | D14: =SUM(E14:L14) -> 120 | I14: 120
A15: 13 | B15: D/END 9.5-10.5mm | C15: each | D15: =SUM(E15:L15) -> 0
A16: 14 | B16: D/END 15.6-17.3mm | C16: each | D16: =SUM(E16:L16) -> 0
A17: 15 | B17: 5+1 dome joint | C17: each | D17: =SUM(E17:L17) -> 120 | I17: 60 | J17: 60
A18: 16 | B18: Drop Cable Closure Cs External Multi Drop Closure | 36 Fibre | 4 x Adaptor Holders MDC | C18: each | D18: =SUM(E18:L18) -> 0
A19: 17 | B19: Feeder Enclosure Corning Enclosure BPEO -S1.5-FDP-DROP N501846A/CMJ | C19: each | D19: =SUM(E19:L19) -> 50 | I19: 50
A20: 18 | B20: LMJ | C20: each | D20: =SUM(E20:L20) -> 0
A21: 19 | B21: Duplex Mid Couplers LC-LC(UPC) | C21: each | D21: =SUM(E21:L21) -> 800 | E21: 800
A22: 20 | B22: Duplex Mid Couplers LC-LC(APC) | C22: each | D22: =SUM(E22:L22) -> 1000 | F22: 1000
A23: 21 | B23: Cartridge 19.1mm | C23: each | D23: =SUM(E23:L23) -> 100 | F23: 100
A24: 22 | B24: Cartriage 9.5mm | C24: each | D24: =SUM(E24:L24) -> 135 | F24: 135
A25: 23 | B25: Splice Protectors-FMSP | C25: each | D25: =SUM(E25:L25) -> 2800 | E25: 800 | F25: 2000
A26: 24 | B26: SPLITTER BARE SM 1-2 | C26: each | D26: =SUM(E26:L26) -> 0
A27: 25 | B27: SPLITTER BARE SM 1-8 | C27: each | D27: =SUM(E27:L27) -> 35 | F27: 35
A28: 26 | B28: SPLITTER BARE SM 1-16 | C28: each | D28: =SUM(E28:L28) -> 155 | E28: 45 | F28: 110
A29: 27 | B29: SPLITTER BARE SM 1-32 | C29: each | D29: =SUM(E29:L29) -> 0
A30: 28 | B30: SPLITTER PRECONNECTERISSED SM 1-8 (UPC) | C30: each | D30: =SUM(E30:L30) -> 400 | E30: 400
A31: 29 | B31: SPLITTER PRECONNECTERISSED SM 1-4 (APC) | C31: each | D31: =SUM(E31:L31) -> 0
A32: 30 | B32: SPLITTER PRECONNECTERISSED SM 1-8 (APC) | C32: each | D32: =SUM(E32:L32) -> 2000 | F32: 2000
A33: 31 | B33: 12F Mini Adss cable / Distribution 2KM&4KM / per roll | C33: m | D33: =SUM(E33:L33) -> 0
A34: 32 | B34: 24F Mini Adss cable / Distribution 2KM&4KM / per roll | C34: m | D34: =SUM(E34:L34) -> 0
A35: 33 | B35: 72F Mini Adss cable / Feeder 2KM&4KM / per roll | C35: m | D35: =SUM(E35:L35) -> 0
A36: 34 | B36: 144F Mini Adss cable / Feeder 2KM&4KM / per roll | C36: m | D36: =SUM(E36:L36) -> 0
A37: 35 | B37: Slack Bins | C37: each | D37: =SUM(E37:L37) -> 205 | H37: 205
A38: 36 | B38: mix plastic pole/wall mount bracket | C38: each | D38: 2150 | J38: 2150
A39: 37 | B39: buckles | C39: Box | D39: 30 | J39: 30
B40: slack bracket | C40: each | D40: 45 | K40: 45974
B41: MDC JOINT | C41: each | D41: 202 | K41: 45974
...

Sheet Sheet1
D6: Fiber Optic Transceiver | E6: 光纤收发器 | F6: PAIR | H6: 单模单纤
D7: cable | E7: 光纤 | F7: M | H7: 12F
D8: Fiber Optic Splice Closure | E8: 光纤终端熔接盒 | F8: EACH | H8: 国标4口
D9: Fiber Splice Closure | E9: 光纤续接盒 | F9: EACH | H9: 国标
D10: Optical Patch Cord | E10: 光纤跳线 | F10: EACH | H10: SC.LC 2M
E11: 光纤尾纤 | F11: EACH | H11: SC/LC 1M
E12: 光纤法兰盘 | F12: EACH | H12: SC/LC
